Workbook

Sheet 📊 경영대시보드_요약
B2: (주)미래소재기술 | 2025~2026 가상소재 판매실적 및 2027 추정 분석 보고서
B3: ※ 상기 작업물은 이해를 돕기위한 가상의 데이터입니다. (25~26년 가상소재 4종 · 5대 거래처 50건 분석)
B5: 25~26 누적 매출액 | D5: 2026 금년 영업이익 | F5: 2026 영업이익률 | H5: 2027 내년 추정 매출 | J5: 2027 내년 추정 영업이익
B6: ==SUM('📋 판매원장_50건'!K5:K54) | D6: ==G25 | F6: ==G27 | H6: ==H20 | J6: ==H25
B8: 1. 가상소재 4종 2025년 vs 2026년 판매실적 비교 요약
B9: 소재코드 | C9: 가상 소재명 | D9: 단위 | E9: 2025 판매량 | F9: 2025 판매대금 | G9: 2026 판매량 | H9: 2026 판매대금 | I9: 판매량 증가율 | J9: 판매대금 증가율 | K9: 2026 매출비중
B10: MAT-01 | C10: 고내열 에폭시 봉지재 (EPX-100) | D10: kg | E10: =SUMIFS('📋 판매원장_50건'!$J$5:$J$54, '📋 판매원장_50건'!$G$5:$G$54, B10, '📋 판매원장_50건'!$D$5:$D$54, 2025) | F10: =SUMIFS('📋 판매원장_50건'!$L$5:$L$54, '📋 판매원장_50건'!$G$5:$G$54, B10, '📋 판매원장_50건'!$D$5:$D$54, 2025) | G10: =SUMIFS('📋 판매원장_50건'!$J$5:$J$54, '📋 판매원장_50건'!$G$5:$G$54, B10, '📋 판매원장_50건'!$D$5:$D$54, 2026) | H10: =SUMIFS('📋 판매원장_50건'!$L$5:$L$54, '📋 판매원장_50건'!$G$5:$G$54, B10, '📋 판매원장_50건'!$D$5:$D$54, 2026) | I10: =(G10-E10)/E10 | J10: =(H10-F10)/F10 | K10: =H10/$H$14
B11: MAT-02 | C11: 초고순도 정밀 세정용제 (SOL-200) | D11: L | E11: =SUMIFS('📋 판매원장_50건'!$J$5:$J$54, '📋 판매원장_50건'!$G$5:$G$54, B11, '📋 판매원장_50건'!$D$5:$D$54, 2025) | F11: =SUMIFS('📋 판매원장_50건'!$L$5:$L$54, '📋 판매원장_50건'!$G$5:$G$54, B11, '📋 판매원장_50건'!$D$5:$D$54, 2025) | G11: =SUMIFS('📋 판매원장_50건'!$J$5:$J$54, '📋 판매원장_50건'!$G$5:$G$54, B11, '📋 판매원장_50건'!$D$5:$D$54, 2026) | H11: =SUMIFS('📋 판매원장_50건'!$L$5:$L$54, '📋 판매원장_50건'!$G$5:$G$54, B11, '📋 판매원장_50건'!$D$5:$D$54, 2026) | I11: =(G11-E11)/E11 | J11: =(H11-F11)/F11 | K11: =H11/$H$14
B12: MAT-03 | C12: 세라믹 방열 절연필러 (TCF-300) | D12: kg | E12: =SUMIFS('📋 판매원장_50건'!$J$5:$J$54, '📋 판매원장_50건'!$G$5:$G$54, B12, '📋 판매원장_50건'!$D$5:$D$54, 2025) | F12: =SUMIFS('📋 판매원장_50건'!$L$5:$L$54, '📋 판매원장_50건'!$G$5:$G$54, B12, '📋 판매원장_50건'!$D$5:$D$54, 2025) | G12: =SUMIFS('📋 판매원장_50건'!$J$5:$J$54, '📋 판매원장_50건'!$G$5:$G$54, B12, '📋 판매원장_50건'!$D$5:$D$54, 2026) | H12: =SUMIFS('📋 판매원장_50건'!$L$5:$L$54, '📋 판매원장_50건'!$G$5:$G$54, B12, '📋 판매원장_50건'!$D$5:$D$54, 2026) | I12: =(G12-E12)/E12 | J12: =(H12-F12)/F12 | K12: =H12/$H$14
B13: MAT-04 | C13: 실리콘 하이브리드 코팅제 (SHC-400) | D13: kg | E13: =SUMIFS('📋 판매원장_50건'!$J$5:$J$54, '📋 판매원장_50건'!$G$5:$G$54, B13, '📋 판매원장_50건'!$D$5:$D$54, 2025) | F13: =SUMIFS('📋 판매원장_50건'!$L$5:$L$54, '📋 판매원장_50건'!$G$5:$G$54, B13, '📋 판매원장_50건'!$D$5:$D$54, 2025) | G13: =SUMIFS('📋 판매원장_50건'!$J$5:$J$54, '📋 판매원장_50건'!$G$5:$G$54, B13, '📋 판매원장_50건'!$D$5:$D$54, 2026) | H13: =SUMIFS('📋 판매원장_50건'!$L$5:$L$54, '📋 판매원장_50건'!$G$5:$G$54, B13, '📋 판매원장_50건'!$D$5:$D$54, 2026) | I13: =(G13-E13)/E13 | J13: =(H13-F13)/F13 | K13: =H13/$H$14
C14: 합계 (Total) | D14: - | E14: =SUM(E10:E13) | F14: =SUM(F10:F13) | G14: =SUM(G10:G13) | H14: =SUM(H10:H13) | I14: =(G14-E14)/E14 | J14: =(H14-F14)/F14 | K14: =SUM(K10:K13)
B17: 2. 금년(2026) 수익 실적 및 내년(2027) 손익 추정치 계산 모델
B18: 구분 (손익계정) | C18: 산출 기준 / 수식 설명 | D18: 2025년 실적 | E18: 2026년 실적 (금년) | F18: 2027년 추정치 (내년) | G18: 25->26 증감 | H18: 26->27 추정증감
B19: ① 총 판매량 (kg·L) | C19: 연간 총 납품 물량 합계 | D19: =E14 | E19: =G14 | F19: =G19*1.25 | G19: =(G19-F19)/ABS(F19) | H19: =(H19-G19)/ABS(G19)
B20: ② 매출액 (판매대금) | C20: 가상소재 4종 공급가액 총합 | D20: =F14 | E20: =H14 | F20: =H20*1.265 | G20: =(G20-F20)/ABS(F20) | H20: =(H20-G20)/ABS(G20)
B21: ③ 매출원가 (원재료/제조) | C21: 가중평균 원가율 적용 | D21: =F20*0.665 | E21: =G20*0.655 | F21: =H20*0.65 | G21: =(G21-F21)/ABS(F21) | H21: =(H21-G21)/ABS(G21)
B22: ④ 매출총이익 | C22: 매출액 - 매출원가 | D22: =F20-F21 | E22: =G20-G21 | F22: =H20-H21 | G22: =(G22-F22)/ABS(F22) | H22: =(H22-G22)/ABS(G22)
B23: 매출총이익률 | C23: 매출총이익 / 매출액 | D23: =F22/F20 | E23: =G22/G20 | F23: =H22/H20 | G23: =(G23-F23)/ABS(F23) | H23: =(H23-G23)/ABS(G23)
B24: ⑤ 판매관리비 (판관비) | C24: 인건비, 물류, 연구개발비 | D24: =F20*0.145 | E24: =G20*0.135 | F24: =H20*0.13 | G24: =(G24-F24)/ABS(F24) | H24: =(H24-G24)/ABS(G24)
B25: ⑥ 영업이익 (수익) | C25: 매출총이익 - 판관비 | D25: =F22-F24 | E25: =G22-G24 | F25: =H22-H24 | G25: =(G25-F25)/ABS(F25) | H25: =(H25-G25)/ABS(G25)
B26: ⑦ 당기순이익 (법인세 차감후) | C26: 영업이익 × (1 - 실효세율 20%) | D26: =F25*0.80 | E26: =G25*0.80 | F26: =H25*0.80 | G26: =(G26-F26)/ABS(F26) | H26: =(H26-G26)/ABS(G26)
B27: 영업이익률 (OP Margin) | C27: 영업이익 / 매출액 | D27: =F25/F20 | E27: =G25/G20 | F27: =H25/H20 | G27: =(G27-F27)/ABS(F27) | H27: =(H27-G27)/ABS(G27)

Sheet 📈 거래처별_실적_비교
B2: 5대 주요 B2B 거래처별 2025년 vs 2026년 판매량 및 판매대금 분석
B4: 거래처코드 | C4: 거래처명 | D4: 소재지 | E4: 2025 거래건수 | F4: 2025 판매대금 | G4: 2026 거래건수 | H4: 2026 판매대금 | I4: 매출 성장률
B5: CLI-01 | C5: (주)한빛케미칼 | D5: 경기 화성 | E5: =COUNTIFS('📋 판매원장_50건'!$F$5:$F$54, C5, '📋 판매원장_50건'!$D$5:$D$54, 2025) | F5: =SUMIFS('📋 판매원장_50건'!$L$5:$L$54, '📋 판매원장_50건'!$F$5:$F$54, C5, '📋 판매원장_50건'!$D$5:$D$54, 2025) | G5: =COUNTIFS('📋 판매원장_50건'!$F$5:$F$54, C5, '📋 판매원장_50건'!$D$5:$D$54, 2026) | H5: =SUMIFS('📋 판매원장_50건'!$L$5:$L$54, '📋 판매원장_50건'!$F$5:$F$54, C5, '📋 판매원장_50건'!$D$5:$D$54, 2026) | I5: =(H5-F5)/F5
B6: CLI-02 | C6: 미래전자소재(주) | D6: 충남 천안 | E6: =COUNTIFS('📋 판매원장_50건'!$F$5:$F$54, C6, '📋 판매원장_50건'!$D$5:$D$54, 2025) | F6: =SUMIFS('📋 판매원장_50건'!$L$5:$L$54, '📋 판매원장_50건'!$F$5:$F$54, C6, '📋 판매원장_50건'!$D$5:$D$54, 2025) | G6: =COUNTIFS('📋 판매원장_50건'!$F$5:$F$54, C6, '📋 판매원장_50건'!$D$5:$D$54, 2026) | H6: =SUMIFS('📋 판매원장_50건'!$L$5:$L$54, '📋 판매원장_50건'!$F$5:$F$54, C6, '📋 판매원장_50건'!$D$5:$D$54, 2026) | I6: =(H6-F6)/F6
B7: CLI-03 | C7: 세안하이테크 | D7: 경북 구미 | E7: =COUNTIFS('📋 판매원장_50건'!$F$5:$F$54, C7, '📋 판매원장_50건'!$D$5:$D$54, 2025) | F7: =SUMIFS('📋 판매원장_50건'!$L$5:$L$54, '📋 판매원장_50건'!$F$5:$F$54, C7, '📋 판매원장_50건'!$D$5:$D$54, 2025) | G7: =COUNTIFS('📋 판매원장_50건'!$F$5:$F$54, C7, '📋 판매원장_50건'!$D$5:$D$54, 2026) | H7: =SUMIFS('📋 판매원장_50건'!$L$5:$L$54, '📋 판매원장_50건'!$F$5:$F$54, C7, '📋 판매원장_50건'!$D$5:$D$54, 2026) | I7: =(H7-F7)/F7
B8: CLI-04 | C8: 대성정밀화학 | D8: 울산 남구 | E8: =COUNTIFS('📋 판매원장_50건'!$F$5:$F$54, C8, '📋 판매원장_50건'!$D$5:$D$54, 2025) | F8: =SUMIFS('📋 판매원장_50건'!$L$5:$L$54, '📋 판매원장_50건'!$F$5:$F$54, C8, '📋 판매원장_50건'!$D$5:$D$54, 2025) | G8: =COUNTIFS('📋 판매원장_50건'!$F$5:$F$54, C8, '📋 판매원장_50건'!$D$5:$D$54, 2026) | H8: =SUMIFS('📋 판매원장_50건'!$L$5:$L$54, '📋 판매원장_50건'!$F$5:$F$54, C8, '📋 판매원장_50건'!$D$5:$D$54, 2026) | I8: =(H8-F8)/F8
B9: CLI-05 | C9: 삼양신소재기술 | D9: 전북 전주 | E9: =COUNTIFS('📋 판매원장_50건'!$F$5:$F$54, C9, '📋 판매원장_50건'!$D$5:$D$54, 2025) | F9: =SUMIFS('📋 판매원장_50건'!$L$5:$L$54, '📋 판매원장_50건'!$F$5:$F$54, C9, '📋 판매원장_50건'!$D$5:$D$54, 2025) | G9: =COUNTIFS('📋 판매원장_50건'!$F$5:$F$54, C9, '📋 판매원장_50건'!$D$5:$D$54, 2026) | H9: =SUMIFS('📋 판매원장_50건'!$L$5:$L$54, '📋 판매원장_50건'!$F$5:$F$54, C9, '📋 판매원장_50건'!$D$5:$D$54, 2026) | I9: =(H9-F9)/F9
C10: 합계 (Total) | D10: - | E10: =SUM(E5:E9) | F10: =SUM(F5:F9) | G10: =SUM(G5:G9) | H10: =SUM(H5:H9) | I10: =(H10-F10)/F10

Sheet 📋 판매원장_50건
B2: (주)미래소재기술 | 2025~2026년 첨단가상소재 납품 거래 원장 (총 50건)
A4: No. | B4: 전표번호 | C4: 거래일자 | D4: 연도 | E4: 분기 | F4: 거래처명 | G4: 품목코드 | H4: 소재 품목명 | I4: 단위 | J4: 판매수량 | K4: 공급단가 | L4: 판매대금(공급가) | M4: 부가세(10%) | N4: 합계금액 | O4: 매출원가 | P4: 매출총이익
A5: 1 | B5: TX-2025-001 | C5: 2025-01-10 | D5: 2025 | E5: 1Q | F5: (주)한빛케미칼 | G5: MAT-01 | H5: 고내열 에폭시 봉지재 (EPX-100) | I5: kg | J5: 1200 | K5: 34000 | L5: =J5*K5 | M5: =L5*0.1 | N5: =L5+M5 | O5: =L5*0.68 | P5: =L5-O5
A6: 2 | B6: TX-2025-002 | C6: 2025-01-17 | D6: 2025 | E6: 1Q | F6: 미래전자소재(주) | G6: MAT-02 | H6: 초고순도 정밀 세정용제 (SOL-200) | I6: L | J6: 850 | K6: 41500 | L6: =J6*K6 | M6: =L6*0.1 | N6: =L6+M6 | O6: =L6*0.62 | P6: =L6-O6
A7: 3 | B7: TX-2025-003 | C7: 2025-02-24 | D7: 2025 | E7: 1Q | F7: 세안하이테크 | G7: MAT-03 | H7: 세라믹 방열 절연필러 (TCF-300) | I7: kg | J7: 1500 | K7: 58000 | L7: =J7*K7 | M7: =L7*0.1 | N7: =L7+M7 | O7: =L7*0.65 | P7: =L7-O7
A8: 4 | B8: TX-2025-004 | C8: 2025-02-10 | D8: 2025 | E8: 1Q | F8: 대성정밀화학 | G8: MAT-04 | H8: 실리콘 하이브리드 코팅제 (SHC-400) | I8: kg | J8: 900 | K8: 28500 | L8: =J8*K8 | M8: =L8*0.1 | N8: =L8+M8 | O8: =L8*0.72 | P8: =L8-O8
A9: 5 | B9: TX-2025-005 | C9: 2025-03-17 | D9: 2025 | E9: 1Q | F9: 삼양신소재기술 | G9: MAT-01 | H9: 고내열 에폭시 봉지재 (EPX-100) | I9: kg | J9: 2100 | K9: 36000 | L9: =J9*K9 | M9: =L9*0.1 | N9: =L9+M9 | O9: =L9*0.68 | P9: =L9-O9
A10: 6 | B10: TX-2025-006 | C10: 2025-03-24 | D10: 2025 | E10: 1Q | F10: (주)한빛케미칼 | G10: MAT-02 | H10: 초고순도 정밀 세정용제 (SOL-200) | I10: L | J10: 1100 | K10: 41000 | L10: =J10*K10 | M10: =L10*0.1 | N10: =L10+M10 | O10: =L10*0.62 | P10: =L10-O10
A11: 7 | B11: TX-2025-007 | C11: 2025-04-10 | D11: 2025 | E11: 2Q | F11: 미래전자소재(주) | G11: MAT-03 | H11: 세라믹 방열 절연필러 (TCF-300) | I11: kg | J11: 750 | K11: 57500 | L11: =J11*K11 | M11: =L11*0.1 | N11: =L11+M11 | O11: =L11*0.65 | P11: =L11-O11
A12: 8 | B12: TX-2025-008 | C12: 2025-04-17 | D12: 2025 | E12: 2Q | F12: 세안하이테크 | G12: MAT-04 | H12: 실리콘 하이브리드 코팅제 (SHC-400) | I12: kg | J12: 1800 | K12: 28000 | L12: =J12*K12 | M12: =L12*0.1 | N12: =L12+M12 | O12: =L12*0.72 | P12: =L12-O12
A13: 9 | B13: TX-2025-009 | C13: 2025-05-24 | D13: 2025 | E13: 2Q | F13: 대성정밀화학 | G13: MAT-01 | H13: 고내열 에폭시 봉지재 (EPX-100) | I13: kg | J13: 1350 | K13: 35500 | L13: =J13*K13 | M13: =L13*0.1 | N13: =L13+M13 | O13: =L13*0.68 | P13: =L13-O13
A14: 10 | B14: TX-2025-010 | C14: 2025-05-10 | D14: 2025 | E14: 2Q | F14: 삼양신소재기술 | G14: MAT-02 | H14: 초고순도 정밀 세정용제 (SOL-200) | I14: L | J14: 950 | K14: 43000 | L14: =J14*K14 | M14: =L14*0.1 | N14: =L14+M14 | O14: =L14*0.62 | P14: =L14-O14
A15: 11 | B15: TX-2025-011 | C15: 2025-06-17 | D15: 2025 | E15: 2Q | F15: (주)한빛케미칼 | G15: MAT-03 | H15: 세라믹 방열 절연필러 (TCF-300) | I15: kg | J15: 1600 | K15: 57000 | L15: =J15*K15 | M15: =L15*0.1 | N15: =L15+M15 | O15: =L15*0.65 | P15: =L15-O15
A16: 12 | B16: TX-2025-012 | C16: 2025-06-24 | D16: 2025 | E16: 2Q | F16: 미래전자소재(주) | G16: MAT-04 | H16: 실리콘 하이브리드 코팅제 (SHC-400) | I16: kg | J16: 2200 | K16: 27500 | L16: =J16*K16 | M16: =L16*0.1 | N16: =L16+M16 | O16: =L16*0.72 | P16: =L16-O16
A17: 13 | B17: TX-2025-013 | C17: 2025-07-10 | D17: 2025 | E17: 3Q | F17: 세안하이테크 | G17: MAT-01 | H17: 고내열 에폭시 봉지재 (EPX-100) | I17: kg | J17: 1400 | K17: 35000 | L17: =J17*K17 | M17: =L17*0.1 | N17: =L17+M17 | O17: =L17*0.68 | P17: =L17-O17
A18: 14 | B18: TX-2025-014 | C18: 2025-07-17 | D18: 2025 | E18: 3Q | F18: 대성정밀화학 | G18: MAT-02 | H18: 초고순도 정밀 세정용제 (SOL-200) | I18: L | J18: 800 | K18: 42500 | L18: =J18*K18 | M18: =L18*0.1 | N18: =L18+M18 | O18: =L18*0.62 | P18: =L18-O18
A19: 15 | B19: TX-2025-015 | C19: 2025-08-24 | D19: 2025 | E19: 3Q | F19: 삼양신소재기술 | G19: MAT-03 | H19: 세라믹 방열 절연필러 (TCF-300) | I19: kg | J19: 1950 | K19: 59000 | L19: =J19*K19 | M19: =L19*0.1 | N19: =L19+M19 | O19: =L19*0.65 | P19: =L19-O19
A20: 16 | B20: TX-2025-016 | C20: 2025-08-10 | D20: 2025 | E20: 3Q | F20: (주)한빛케미칼 | G20: MAT-04 | H20: 실리콘 하이브리드 코팅제 (SHC-400) | I20: kg | J20: 1250 | K20: 27000 | L20: =J20*K20 | M20: =L20*0.1 | N20: =L20+M20 | O20: =L20*0.72 | P20: =L20-O20
A21: 17 | B21: TX-2025-017 | C21: 2025-09-17 | D21: 2025 | E21: 3Q | F21: 미래전자소재(주) | G21: MAT-01 | H21: 고내열 에폭시 봉지재 (EPX-100) | I21: kg | J21: 1700 | K21: 34500 | L21: =J21*K21 | M21: =L21*0.1 | N21: =L21+M21 | O21: =L21*0.68 | P21: =L21-O21
A22: 18 | B22: TX-2025-018 | C22: 2025-09-24 | D22: 2025 | E22: 3Q | F22: 세안하이테크 | G22: MAT-02 | H22: 초고순도 정밀 세정용제 (SOL-200) | I22: L | J22: 2400 | K22: 42000 | L22: =J22*K22 | M22: =L22*0.1 | N22: =L22+M22 | O22: =L22*0.62 | P22: =L22-O22
A23: 19 | B23: TX-2025-019 | C23: 2025-10-10 | D23: 2025 | E23: 4Q | F23: 대성정밀화학 | G23: MAT-03 | H23: 세라믹 방열 절연필러 (TCF-300) | I23: kg | J23: 1150 | K23: 58500 | L23: =J23*K23 | M23: =L23*0.1 | N23: =L23+M23 | O23: =L23*0.65 | P23: =L23-O23
A24: 20 | B24: TX-2025-020 | C24: 2025-10-17 | D24: 2025 | E24: 4Q | F24: 삼양신소재기술 | G24: MAT-04 | H24: 실리콘 하이브리드 코팅제 (SHC-400) | I24: kg | J24: 900 | K24: 29000 | L24: =J24*K24 | M24: =L24*0.1 | N24: =L24+M24 | O24: =L24*0.72 | P24: =L24-O24
A25: 21 | B25: TX-2025-021 | C25: 2025-11-24 | D25: 2025 | E25: 4Q | F25: (주)한빛케미칼 | G25: MAT-01 | H25: 고내열 에폭시 봉지재 (EPX-100) | I25: kg | J25: 1850 | K25: 34000 | L25: =J25*K25 | M25: =L25*0.1 | N25: =L25+M25 | O25: =L25*0.68 | P25: =L25-O25
A26: 22 | B26: TX-2025-022 | C26: 2025-11-10 | D26: 2025 | E26: 4Q | F26: 미래전자소재(주) | G26: MAT-02 | H26: 초고순도 정밀 세정용제 (SOL-200) | I26: L | J26: 1300 | K26: 41500 | L26: =J26*K26 | M26: =L26*0.1 | N26: =L26+M26 | O26: =L26*0.62 | P26: =L26-O26
A27: 23 | B27: TX-2025-023 | C27: 2025-12-17 | D27: 2025 | E27: 4Q | F27: 세안하이테크 | G27: MAT-03 | H27: 세라믹 방열 절연필러 (TCF-300) | I27: kg | J27: 2100 | K27: 58000 | L27: =J27*K27 | M27: =L27*0.1 | N27: =L27+M27 | O27: =L27*0.65 | P27: =L27-O27
A28: 24 | B28: TX-2025-024 | C28: 2025-12-24 | D28: 2025 | E28: 4Q | F28: 대성정밀화학 | G28: MAT-04 | H28: 실리콘 하이브리드 코팅제 (SHC-400) | I28: kg | J28: 1500 | K28: 28500 | L28: =J28*K28 | M28: =L28*0.1 | N28: =L28+M28 | O28: =L28*0.72 | P28: =L28-O28
A29: 25 | B29: TX-2025-025 | C29: 2025-12-10 | D29: 2025 | E29: 4Q | F29: 삼양신소재기술 | G29: MAT-01 | H29: 고내열 에폭시 봉지재 (EPX-100) | I29: kg | J29: 2500 | K29: 36000 | L29: =J29*K29 | M29: =L29*0.1 | N29: =L29+M29 | O29: =L29*0.68 | P29: =L29-O29
A30: 26 | B30: TX-2026-001 | C30: 2026-01-08 | D30: 2026 | E30: 1Q | F30: 세안하이테크 | G30: MAT-02 | H30: 초고순도 정밀 세정용제 (SOL-200) | I30: L | J30: 1500 | K30: 42400 | L30: =J30*K30 | M30: =L30*0.1 | N30: =L30+M30 | O30: =L30*0.62 | P30: =L30-O30
A31: 27 | B31: TX-2026-002 | C31: 2026-01-16 | D31: 2026 | E31: 1Q | F31: 대성정밀화학 | G31: MAT-03 | H31: 세라믹 방열 절연필러 (TCF-300) | I31: kg | J31: 1100 | K31: 59000 | L31: =J31*K31 | M31: =L31*0.1 | N31: =L31+M31 | O31: =L31*0.65 | P31: =L31-O31
A32: 28 | B32: TX-2026-003 | C32: 2026-02-24 | D32: 2026 | E32: 1Q | F32: 삼양신소재기술 | G32: MAT-04 | H32: 실리콘 하이브리드 코팅제 (SHC-400) | I32: kg | J32: 1900 | K32: 29600 | L32: =J32*K32 | M32: =L32*0.1 | N32: =L32+M32 | O32: =L32*0.72 | P32: =L32-O32
A33: 29 | B33: TX-2026-004 | C33: 2026-02-08 | D33: 2026 | E33: 1Q | F33: (주)한빛케미칼 | G33: MAT-01 | H33: 고내열 에폭시 봉지재 (EPX-100) | I33: kg | J33: 1200 | K33: 37200 | L33: =J33*K33 | M33: =L33*0.1 | N33: =L33+M33 | O33: =L33*0.68 | P33: =L33-O33
A34: 30 | B34: TX-2026-005 | C34: 2026-03-16 | D34: 2026 | E34: 1Q | F34: 미래전자소재(주) | G34: MAT-02 | H34: 초고순도 정밀 세정용제 (SOL-200) | I34: L | J34: 2600 | K34: 42400 | L34: =J34*K34 | M34: =L34*0.1 | N34: =L34+M34 | O34: =L34*0.62 | P34: =L34-O34
A35: 31 | B35: TX-2026-006 | C35: 2026-03-24 | D35: 2026 | E35: 1Q | F35: 세안하이테크 | G35: MAT-03 | H35: 세라믹 방열 절연필러 (TCF-300) | I35: kg | J35: 1450 | K35: 59000 | L35: =J35*K35 | M35: =L35*0.1 | N35: =L35+M35 | O35: =L35*0.65 | P35: =L35-O35
A36: 32 | B36: TX-2026-007 | C36: 2026-04-08 | D36: 2026 | E36: 2Q | F36: 대성정밀화학 | G36: MAT-04 | H36: 실리콘 하이브리드 코팅제 (SHC-400) | I36: kg | J36: 980 | K36: 29600 | L36: =J36*K36 | M36: =L36*0.1 | N36: =L36+M36 | O36: =L36*0.72 | P36: =L36-O36
A37: 33 | B37: TX-2026-008 | C37: 2026-04-16 | D37: 2026 | E37: 2Q | F37: 삼양신소재기술 | G37: MAT-01 | H37: 고내열 에폭시 봉지재 (EPX-100) | I37: kg | J37: 2250 | K37: 37200 | L37: =J37*K37 | M37: =L37*0.1 | N37: =L37+M37 | O37: =L37*0.68 | P37: =L37-O37
A38: 34 | B38: TX-2026-009 | C38: 2026-05-24 | D38: 2026 | E38: 2Q | F38: (주)한빛케미칼 | G38: MAT-02 | H38: 초고순도 정밀 세정용제 (SOL-200) | I38: L | J38: 1700 | K38: 42400 | L38: =J38*K38 | M38: =L38*0.1 | N38: =L38+M38 | O38: =L38*0.62 | P38: =L38-O38
A39: 35 | B39: TX-2026-010 | C39: 2026-05-08 | D39: 2026 | E39: 2Q | F39: 미래전자소재(주) | G39: MAT-03 | H39: 세라믹 방열 절연필러 (TCF-300) | I39: kg | J39: 1250 | K39: 59000 | L39: =J39*K39 | M39: =L39*0.1 | N39: =L39+M39 | O39: =L39*0.65 | P39: =L39-O39
A40: 36 | B40: TX-2026-011 | C40: 2026-06-16 | D40: 2026 | E40: 2Q | F40: 세안하이테크 | G40: MAT-04 | H40: 실리콘 하이브리드 코팅제 (SHC-400) | I40: kg | J40: 2050 | K40: 29600 | L40: =J40*K40 | M40: =L40*0.1 | N40: =L40+M40 | O40: =L40*0.72 | P40: =L40-O40
A41: 37 | B41: TX-2026-012 | C41: 2026-06-24 | D41: 2026 | E41: 2Q | F41: 대성정밀화학 | G41: MAT-01 | H41: 고내열 에폭시 봉지재 (EPX-100) | I41: kg | J41: 2750 | K41: 37200 | L41: =J41*K41 | M41: =L41*0.1 | N41: =L41+M41 | O41: =L41*0.68 | P41: =L41-O41
A42: 38 | B42: TX-2026-013 | C42: 2026-07-08 | D42: 2026 | E42: 3Q | F42: 삼양신소재기술 | G42: MAT-02 | H42: 초고순도 정밀 세정용제 (SOL-200) | I42: L | J42: 1800 | K42: 42400 | L42: =J42*K42 | M42: =L42*0.1 | N42: =L42+M42 | O42: =L42*0.62 | P42: =L42-O42
...

Sheet 🔮 2027_손익추정모델
B2: 2027년도 매출 및 영업수익 예측 시나리오 (보수적 / 기준 / 낙관적)
B4: 시나리오 구분 | C4: 성장률 가정 | D4: 2027 예상판매량 | E4: 2027 예상매출액 | F4: 예상매출원가 | G4: 예상판관비 | H4: 예상영업이익 | I4: 영업이익률
B5: 보수적 시나리오 (Conservative) | C5: 0.15 | D5: ='📊 경영대시보드_요약'!G19*1.15 | E5: ='📊 경영대시보드_요약'!G20*1.15 | F5: =F5*0.66 | G5: =F5*0.14 | H5: =F5-G5-H5 | I5: =I5/F5
B6: 기준 시나리오 (Base / 추천모델) | C6: 0.265 | D6: ='📊 경영대시보드_요약'!G19*1.25 | E6: ='📊 경영대시보드_요약'!G20*1.265 | F6: =F6*0.65 | G6: =F6*0.13 | H6: =F6-G6-H6 | I6: =I6/F6
B7: 낙관적 시나리오 (Optimistic) | C7: 0.38 | D7: ='📊 경영대시보드_요약'!G19*1.35 | E7: ='📊 경영대시보드_요약'!G20*1.38 | F7: =F7*0.64 | G7: =F7*0.125 | H7: =F7-G7-H7 | I7: =I7/F7
